Workbook

Sheet Dashboard
A1: Injection Mold Job Dashboard
A2: Combined view across New Tooling Jobs and Reorders. Click a tab below to edit underlying data.
A3: =CONCATENATE("Last opened: ", TEXT(TODAY(),"dddd, mmmm d, yyyy"))
A5: Active Jobs | C5: New Tooling | E5: Reorders | G5: Overdue
A6: =COUNTIFS('New Tooling Jobs'!A13:A62,"<>",'New Tooling Jobs'!E13:E62,"<>Completed",'New Tooling Jobs'!E13:E62,"<>")+COUNTIFS(Reorders!A13:A62,"<>",Reorders!E13:E62,"<>Completed",Reorders!E13:E62,"<>") | C6: =COUNTIFS('New Tooling Jobs'!A13:A62,"<>",'New Tooling Jobs'!E13:E62,"<>Completed",'New Tooling Jobs'!E13:E62,"<>") | E6: =COUNTIFS(Reorders!A13:A62,"<>",Reorders!E13:E62,"<>Completed",Reorders!E13:E62,"<>") | G6: =SUMPRODUCT(('New Tooling Jobs'!X13:X62<>"")*(IFERROR('New Tooling Jobs'!X13:X62+0,99999)<0)*('New Tooling Jobs'!E13:E62<>"Completed"))+SUMPRODUCT((Reorders!T13:T62<>"")*(IFERROR(Reorders!T13:T62+0,99999)<0)*(Reorders!E13:E62<>"Completed"))
A9: Job # | B9: Job Type | C9: Customer | D9: Stage | E9: Customer PO # | F9: Molder PO # | G9: Next Action / Waiting On
A10: =IFERROR(IF(1<=COUNTIFS('New Tooling Jobs'!A$13:A$62,"<>",'New Tooling Jobs'!E$13:E$62,"<>Completed"),INDEX('New Tooling Jobs'!A$13:A$62,MATCH(1,'New Tooling Jobs'!AG$13:AG$62,0)),INDEX(Reorders!A$13:A$62,MATCH(1-COUNTIFS('New Tooling Jobs'!A$13:A$62,"<>",'New Tooling Jobs'!E$13:E$62,"<>Completed"),Reorders!AC$13:AC$62,0))),"") | B10: =IFERROR(IF(1<=COUNTIFS('New Tooling Jobs'!A$13:A$62,"<>",'New Tooling Jobs'!E$13:E$62,"<>Completed"),IF(INDEX('New Tooling Jobs'!A$13:A$62,MATCH(1,'New Tooling Jobs'!AG$13:AG$62,0))<>"","New Tooling",""),IF(INDEX(Reorders!A$13:A$62,MATCH(1-COUNTIFS('New Tooling Jobs'!A$13:A$62,"<>",'New Tooling Jobs'!E$13:E$62,"<>Completed"),Reorders!AC$13:AC$62,0))<>"","Reorder","")),"") | C10: =IFERROR(IF(1<=COUNTIFS('New Tooling Jobs'!A$13:A$62,"<>",'New Tooling Jobs'!E$13:E$62,"<>Completed"),INDEX('New Tooling Jobs'!B$13:B$62,MATCH(1,'New Tooling Jobs'!AG$13:AG$62,0)),INDEX(Reorders!B$13:B$62,MATCH(1-COUNTIFS('New Tooling Jobs'!A$13:A$62,"<>",'New Tooling Jobs'!E$13:E$62,"<>Completed"),Reorders!AC$13:AC$62,0))),"") | D10: =IFERROR(IF(1<=COUNTIFS('New Tooling Jobs'!A$13:A$62,"<>",'New Tooling Jobs'!E$13:E$62,"<>Completed"),INDEX('New Tooling Jobs'!E$13:E$62,MATCH(1,'New Tooling Jobs'!AG$13:AG$62,0)),INDEX(Reorders!E$13:E$62,MATCH(1-COUNTIFS('New Tooling Jobs'!A$13:A$62,"<>",'New Tooling Jobs'!E$13:E$62,"<>Completed"),Reorders!AC$13:AC$62,0))),"") | E10: =IFERROR(IF(1<=COUNTIFS('New Tooling Jobs'!A$13:A$62,"<>",'New Tooling Jobs'!E$13:E$62,"<>Completed"),INDEX('New Tooling Jobs'!G$13:G$62,MATCH(1,'New Tooling Jobs'!AG$13:AG$62,0)),INDEX(Reorders!G$13:G$62,MATCH(1-COUNTIFS('New Tooling Jobs'!A$13:A$62,"<>",'New Tooling Jobs'!E$13:E$62,"<>Completed"),Reorders!AC$13:AC$62,0))),"") | F10: =IFERROR(IF(1<=COUNTIFS('New Tooling Jobs'!A$13:A$62,"<>",'New Tooling Jobs'!E$13:E$62,"<>Completed"),INDEX('New Tooling Jobs'!H$13:H$62,MATCH(1,'New Tooling Jobs'!AG$13:AG$62,0)),INDEX(Reorders!H$13:H$62,MATCH(1-COUNTIFS('New Tooling Jobs'!A$13:A$62,"<>",'New Tooling Jobs'!E$13:E$62,"<>Completed"),Reorders!AC$13:AC$62,0))),"") | G10: =IFERROR(IF(1<=COUNTIFS('New Tooling Jobs'!A$13:A$62,"<>",'New Tooling Jobs'!E$13:E$62,"<>Completed"),INDEX('New Tooling Jobs'!I$13:I$62,MATCH(1,'New Tooling Jobs'!AG$13:AG$62,0)),INDEX(Reorders!I$13:I$62,MATCH(1-COUNTIFS('New Tooling Jobs'!A$13:A$62,"<>",'New Tooling Jobs'!E$13:E$62,"<>Completed"),Reorders!AC$13:AC$62,0))),"")
A11: =IFERROR(IF(2<=COUNTIFS('New Tooling Jobs'!A$13:A$62,"<>",'New Tooling Jobs'!E$13:E$62,"<>Completed"),INDEX('New Tooling Jobs'!A$13:A$62,MATCH(2,'New Tooling Jobs'!AG$13:AG$62,0)),INDEX(Reorders!A$13:A$62,MATCH(2-COUNTIFS('New Tooling Jobs'!A$13:A$62,"<>",'New Tooling Jobs'!E$13:E$62,"<>Completed"),Reorders!AC$13:AC$62,0))),"") | B11: =IFERROR(IF(2<=COUNTIFS('New Tooling Jobs'!A$13:A$62,"<>",'New Tooling Jobs'!E$13:E$62,"<>Completed"),IF(INDEX('New Tooling Jobs'!A$13:A$62,MATCH(2,'New Tooling Jobs'!AG$13:AG$62,0))<>"","New Tooling",""),IF(INDEX(Reorders!A$13:A$62,MATCH(2-COUNTIFS('New Tooling Jobs'!A$13:A$62,"<>",'New Tooling Jobs'!E$13:E$62,"<>Completed"),Reorders!AC$13:AC$62,0))<>"","Reorder","")),"") | C11: =IFERROR(IF(2<=COUNTIFS('New Tooling Jobs'!A$13:A$62,"<>",'New Tooling Jobs'!E$13:E$62,"<>Completed"),INDEX('New Tooling Jobs'!B$13:B$62,MATCH(2,'New Tooling Jobs'!AG$13:AG$62,0)),INDEX(Reorders!B$13:B$62,MATCH(2-COUNTIFS('New Tooling Jobs'!A$13:A$62,"<>",'New Tooling Jobs'!E$13:E$62,"<>Completed"),Reorders!AC$13:AC$62,0))),"") | D11: =IFERROR(IF(2<=COUNTIFS('New Tooling Jobs'!A$13:A$62,"<>",'New Tooling Jobs'!E$13:E$62,"<>Completed"),INDEX('New Tooling Jobs'!E$13:E$62,MATCH(2,'New Tooling Jobs'!AG$13:AG$62,0)),INDEX(Reorders!E$13:E$62,MATCH(2-COUNTIFS('New Tooling Jobs'!A$13:A$62,"<>",'New Tooling Jobs'!E$13:E$62,"<>Completed"),Reorders!AC$13:AC$62,0))),"") | E11: =IFERROR(IF(2<=COUNTIFS('New Tooling Jobs'!A$13:A$62,"<>",'New Tooling Jobs'!E$13:E$62,"<>Completed"),INDEX('New Tooling Jobs'!G$13:G$62,MATCH(2,'New Tooling Jobs'!AG$13:AG$62,0)),INDEX(Reorders!G$13:G$62,MATCH(2-COUNTIFS('New Tooling Jobs'!A$13:A$62,"<>",'New Tooling Jobs'!E$13:E$62,"<>Completed"),Reorders!AC$13:AC$62,0))),"") | F11: =IFERROR(IF(2<=COUNTIFS('New Tooling Jobs'!A$13:A$62,"<>",'New Tooling Jobs'!E$13:E$62,"<>Completed"),INDEX('New Tooling Jobs'!H$13:H$62,MATCH(2,'New Tooling Jobs'!AG$13:AG$62,0)),INDEX(Reorders!H$13:H$62,MATCH(2-COUNTIFS('New Tooling Jobs'!A$13:A$62,"<>",'New Tooling Jobs'!E$13:E$62,"<>Completed"),Reorders!AC$13:AC$62,0))),"") | G11: =IFERROR(IF(2<=COUNTIFS('New Tooling Jobs'!A$13:A$62,"<>",'New Tooling Jobs'!E$13:E$62,"<>Completed"),INDEX('New Tooling Jobs'!I$13:I$62,MATCH(2,'New Tooling Jobs'!AG$13:AG$62,0)),INDEX(Reorders!I$13:I$62,MATCH(2-COUNTIFS('New Tooling Jobs'!A$13:A$62,"<>",'New Tooling Jobs'!E$13:E$62,"<>Completed"),Reorders!AC$13:AC$62,0))),"")
A12: =IFERROR(IF(3<=COUNTIFS('New Tooling Jobs'!A$13:A$62,"<>",'New Tooling Jobs'!E$13:E$62,"<>Completed"),INDEX('New Tooling Jobs'!A$13:A$62,MATCH(3,'New Tooling Jobs'!AG$13:AG$62,0)),INDEX(Reorders!A$13:A$62,MATCH(3-COUNTIFS('New Tooling Jobs'!A$13:A$62,"<>",'New Tooling Jobs'!E$13:E$62,"<>Completed"),Reorders!AC$13:AC$62,0))),"") | B12: =IFERROR(IF(3<=COUNTIFS('New Tooling Jobs'!A$13:A$62,"<>",'New Tooling Jobs'!E$13:E$62,"<>Completed"),IF(INDEX('New Tooling Jobs'!A$13:A$62,MATCH(3,'New Tooling Jobs'!AG$13:AG$62,0))<>"","New Tooling",""),IF(INDEX(Reorders!A$13:A$62,MATCH(3-COUNTIFS('New Tooling Jobs'!A$13:A$62,"<>",'New Tooling Jobs'!E$13:E$62,"<>Completed"),Reorders!AC$13:AC$62,0))<>"","Reorder","")),"") | C12: =IFERROR(IF(3<=COUNTIFS('New Tooling Jobs'!A$13:A$62,"<>",'New Tooling Jobs'!E$13:E$62,"<>Completed"),INDEX('New Tooling Jobs'!B$13:B$62,MATCH(3,'New Tooling Jobs'!AG$13:AG$62,0)),INDEX(Reorders!B$13:B$62,MATCH(3-COUNTIFS('New Tooling Jobs'!A$13:A$62,"<>",'New Tooling Jobs'!E$13:E$62,"<>Completed"),Reorders!AC$13:AC$62,0))),"") | D12: =IFERROR(IF(3<=COUNTIFS('New Tooling Jobs'!A$13:A$62,"<>",'New Tooling Jobs'!E$13:E$62,"<>Completed"),INDEX('New Tooling Jobs'!E$13:E$62,MATCH(3,'New Tooling Jobs'!AG$13:AG$62,0)),INDEX(Reorders!E$13:E$62,MATCH(3-COUNTIFS('New Tooling Jobs'!A$13:A$62,"<>",'New Tooling Jobs'!E$13:E$62,"<>Completed"),Reorders!AC$13:AC$62,0))),"") | E12: =IFERROR(IF(3<=COUNTIFS('New Tooling Jobs'!A$13:A$62,"<>",'New Tooling Jobs'!E$13:E$62,"<>Completed"),INDEX('New Tooling Jobs'!G$13:G$62,MATCH(3,'New Tooling Jobs'!AG$13:AG$62,0)),INDEX(Reorders!G$13:G$62,MATCH(3-COUNTIFS('New Tooling Jobs'!A$13:A$62,"<>",'New Tooling Jobs'!E$13:E$62,"<>Completed"),Reorders!AC$13:AC$62,0))),"") | F12: =IFERROR(IF(3<=COUNTIFS('New Tooling Jobs'!A$13:A$62,"<>",'New Tooling Jobs'!E$13:E$62,"<>Completed"),INDEX('New Tooling Jobs'!H$13:H$62,MATCH(3,'New Tooling Jobs'!AG$13:AG$62,0)),INDEX(Reorders!H$13:H$62,MATCH(3-COUNTIFS('New Tooling Jobs'!A$13:A$62,"<>",'New Tooling Jobs'!E$13:E$62,"<>Completed"),Reorders!AC$13:AC$62,0))),"") | G12: =IFERROR(IF(3<=COUNTIFS('New Tooling Jobs'!A$13:A$62,"<>",'New Tooling Jobs'!E$13:E$62,"<>Completed"),INDEX('New Tooling Jobs'!I$13:I$62,MATCH(3,'New Tooling Jobs'!AG$13:AG$62,0)),INDEX(Reorders!I$13:I$62,MATCH(3-COUNTIFS('New Tooling Jobs'!A$13:A$62,"<>",'New Tooling Jobs'!E$13:E$62,"<>Completed"),Reorders!AC$13:AC$62,0))),"")
A13: =IFERROR(IF(4<=COUNTIFS('New Tooling Jobs'!A$13:A$62,"<>",'New Tooling Jobs'!E$13:E$62,"<>Completed"),INDEX('New Tooling Jobs'!A$13:A$62,MATCH(4,'New Tooling Jobs'!AG$13:AG$62,0)),INDEX(Reorders!A$13:A$62,MATCH(4-COUNTIFS('New Tooling Jobs'!A$13:A$62,"<>",'New Tooling Jobs'!E$13:E$62,"<>Completed"),Reorders!AC$13:AC$62,0))),"") | B13: =IFERROR(IF(4<=COUNTIFS('New Tooling Jobs'!A$13:A$62,"<>",'New Tooling Jobs'!E$13:E$62,"<>Completed"),IF(INDEX('New Tooling Jobs'!A$13:A$62,MATCH(4,'New Tooling Jobs'!AG$13:AG$62,0))<>"","New Tooling",""),IF(INDEX(Reorders!A$13:A$62,MATCH(4-COUNTIFS('New Tooling Jobs'!A$13:A$62,"<>",'New Tooling Jobs'!E$13:E$62,"<>Completed"),Reorders!AC$13:AC$62,0))<>"","Reorder","")),"") | C13: =IFERROR(IF(4<=COUNTIFS('New Tooling Jobs'!A$13:A$62,"<>",'New Tooling Jobs'!E$13:E$62,"<>Completed"),INDEX('New Tooling Jobs'!B$13:B$62,MATCH(4,'New Tooling Jobs'!AG$13:AG$62,0)),INDEX(Reorders!B$13:B$62,MATCH(4-COUNTIFS('New Tooling Jobs'!A$13:A$62,"<>",'New Tooling Jobs'!E$13:E$62,"<>Completed"),Reorders!AC$13:AC$62,0))),"") | D13: =IFERROR(IF(4<=COUNTIFS('New Tooling Jobs'!A$13:A$62,"<>",'New Tooling Jobs'!E$13:E$62,"<>Completed"),INDEX('New Tooling Jobs'!E$13:E$62,MATCH(4,'New Tooling Jobs'!AG$13:AG$62,0)),INDEX(Reorders!E$13:E$62,MATCH(4-COUNTIFS('New Tooling Jobs'!A$13:A$62,"<>",'New Tooling Jobs'!E$13:E$62,"<>Completed"),Reorders!AC$13:AC$62,0))),"") | E13: =IFERROR(IF(4<=COUNTIFS('New Tooling Jobs'!A$13:A$62,"<>",'New Tooling Jobs'!E$13:E$62,"<>Completed"),INDEX('New Tooling Jobs'!G$13:G$62,MATCH(4,'New Tooling Jobs'!AG$13:AG$62,0)),INDEX(Reorders!G$13:G$62,MATCH(4-COUNTIFS('New Tooling Jobs'!A$13:A$62,"<>",'New Tooling Jobs'!E$13:E$62,"<>Completed"),Reorders!AC$13:AC$62,0))),"") | F13: =IFERROR(IF(4<=COUNTIFS('New Tooling Jobs'!A$13:A$62,"<>",'New Tooling Jobs'!E$13:E$62,"<>Completed"),INDEX('New Tooling Jobs'!H$13:H$62,MATCH(4,'New Tooling Jobs'!AG$13:AG$62,0)),INDEX(Reorders!H$13:H$62,MATCH(4-COUNTIFS('New Tooling Jobs'!A$13:A$62,"<>",'New Tooling Jobs'!E$13:E$62,"<>Completed"),Reorders!AC$13:AC$62,0))),"") | G13: =IFERROR(IF(4<=COUNTIFS('New Tooling Jobs'!A$13:A$62,"<>",'New Tooling Jobs'!E$13:E$62,"<>Completed"),INDEX('New Tooling Jobs'!I$13:I$62,MATCH(4,'New Tooling Jobs'!AG$13:AG$62,0)),INDEX(Reorders!I$13:I$62,MATCH(4-COUNTIFS('New Tooling Jobs'!A$13:A$62,"<>",'New Tooling Jobs'!E$13:E$62,"<>Completed"),Reorders!AC$13:AC$62,0))),"")
A14: =IFERROR(IF(5<=COUNTIFS('New Tooling Jobs'!A$13:A$62,"<>",'New Tooling Jobs'!E$13:E$62,"<>Completed"),INDEX('New Tooling Jobs'!A$13:A$62,MATCH(5,'New Tooling Jobs'!AG$13:AG$62,0)),INDEX(Reorders!A$13:A$62,MATCH(5-COUNTIFS('New Tooling Jobs'!A$13:A$62,"<>",'New Tooling Jobs'!E$13:E$62,"<>Completed"),Reorders!AC$13:AC$62,0))),"") | B14: =IFERROR(IF(5<=COUNTIFS('New Tooling Jobs'!A$13:A$62,"<>",'New Tooling Jobs'!E$13:E$62,"<>Completed"),IF(INDEX('New Tooling Jobs'!A$13:A$62,MATCH(5,'New Tooling Jobs'!AG$13:AG$62,0))<>"","New Tooling",""),IF(INDEX(Reorders!A$13:A$62,MATCH(5-COUNTIFS('New Tooling Jobs'!A$13:A$62,"<>",'New Tooling Jobs'!E$13:E$62,"<>Completed"),Reorders!AC$13:AC$62,0))<>"","Reorder","")),"") | C14: =IFERROR(IF(5<=COUNTIFS('New Tooling Jobs'!A$13:A$62,"<>",'New Tooling Jobs'!E$13:E$62,"<>Completed"),INDEX('New Tooling Jobs'!B$13:B$62,MATCH(5,'New Tooling Jobs'!AG$13:AG$62,0)),INDEX(Reorders!B$13:B$62,MATCH(5-COUNTIFS('New Tooling Jobs'!A$13:A$62,"<>",'New Tooling Jobs'!E$13:E$62,"<>Completed"),Reorders!AC$13:AC$62,0))),"") | D14: =IFERROR(IF(5<=COUNTIFS('New Tooling Jobs'!A$13:A$62,"<>",'New Tooling Jobs'!E$13:E$62,"<>Completed"),INDEX('New Tooling Jobs'!E$13:E$62,MATCH(5,'New Tooling Jobs'!AG$13:AG$62,0)),INDEX(Reorders!E$13:E$62,MATCH(5-COUNTIFS('New Tooling Jobs'!A$13:A$62,"<>",'New Tooling Jobs'!E$13:E$62,"<>Completed"),Reorders!AC$13:AC$62,0))),"") | E14: =IFERROR(IF(5<=COUNTIFS('New Tooling Jobs'!A$13:A$62,"<>",'New Tooling Jobs'!E$13:E$62,"<>Completed"),INDEX('New Tooling Jobs'!G$13:G$62,MATCH(5,'New Tooling Jobs'!AG$13:AG$62,0)),INDEX(Reorders!G$13:G$62,MATCH(5-COUNTIFS('New Tooling Jobs'!A$13:A$62,"<>",'New Tooling Jobs'!E$13:E$62,"<>Completed"),Reorders!AC$13:AC$62,0))),"") | F14: =IFERROR(IF(5<=COUNTIFS('New Tooling Jobs'!A$13:A$62,"<>",'New Tooling Jobs'!E$13:E$62,"<>Completed"),INDEX('New Tooling Jobs'!H$13:H$62,MATCH(5,'New Tooling Jobs'!AG$13:AG$62,0)),INDEX(Reorders!H$13:H$62,MATCH(5-COUNTIFS('New Tooling Jobs'!A$13:A$62,"<>",'New Tooling Jobs'!E$13:E$62,"<>Completed"),Reorders!AC$13:AC$62,0))),"") | G14: =IFERROR(IF(5<=COUNTIFS('New Tooling Jobs'!A$13:A$62,"<>",'New Tooling Jobs'!E$13:E$62,"<>Completed"),INDEX('New Tooling Jobs'!I$13:I$62,MATCH(5,'New Tooling Jobs'!AG$13:AG$62,0)),INDEX(Reorders!I$13:I$62,MATCH(5-COUNTIFS('New Tooling Jobs'!A$13:A$62,"<>",'New Tooling Jobs'!E$13:E$62,"<>Completed"),Reorders!AC$13:AC$62,0))),"")
A15: =IFERROR(IF(6<=COUNTIFS('New Tooling Jobs'!A$13:A$62,"<>",'New Tooling Jobs'!E$13:E$62,"<>Completed"),INDEX('New Tooling Jobs'!A$13:A$62,MATCH(6,'New Tooling Jobs'!AG$13:AG$62,0)),INDEX(Reorders!A$13:A$62,MATCH(6-COUNTIFS('New Tooling Jobs'!A$13:A$62,"<>",'New Tooling Jobs'!E$13:E$62,"<>Completed"),Reorders!AC$13:AC$62,0))),"") | B15: =IFERROR(IF(6<=COUNTIFS('New Tooling Jobs'!A$13:A$62,"<>",'New Tooling Jobs'!E$13:E$62,"<>Completed"),IF(INDEX('New Tooling Jobs'!A$13:A$62,MATCH(6,'New Tooling Jobs'!AG$13:AG$62,0))<>"","New Tooling",""),IF(INDEX(Reorders!A$13:A$62,MATCH(6-COUNTIFS('New Tooling Jobs'!A$13:A$62,"<>",'New Tooling Jobs'!E$13:E$62,"<>Completed"),Reorders!AC$13:AC$62,0))<>"","Reorder","")),"") | C15: =IFERROR(IF(6<=COUNTIFS('New Tooling Jobs'!A$13:A$62,"<>",'New Tooling Jobs'!E$13:E$62,"<>Completed"),INDEX('New Tooling Jobs'!B$13:B$62,MATCH(6,'New Tooling Jobs'!AG$13:AG$62,0)),INDEX(Reorders!B$13:B$62,MATCH(6-COUNTIFS('New Tooling Jobs'!A$13:A$62,"<>",'New Tooling Jobs'!E$13:E$62,"<>Completed"),Reorders!AC$13:AC$62,0))),"") | D15: =IFERROR(IF(6<=COUNTIFS('New Tooling Jobs'!A$13:A$62,"<>",'New Tooling Jobs'!E$13:E$62,"<>Completed"),INDEX('New Tooling Jobs'!E$13:E$62,MATCH(6,'New Tooling Jobs'!AG$13:AG$62,0)),INDEX(Reorders!E$13:E$62,MATCH(6-COUNTIFS('New Tooling Jobs'!A$13:A$62,"<>",'New Tooling Jobs'!E$13:E$62,"<>Completed"),Reorders!AC$13:AC$62,0))),"") | E15: =IFERROR(IF(6<=COUNTIFS('New Tooling Jobs'!A$13:A$62,"<>",'New Tooling Jobs'!E$13:E$62,"<>Completed"),INDEX('New Tooling Jobs'!G$13:G$62,MATCH(6,'New Tooling Jobs'!AG$13:AG$62,0)),INDEX(Reorders!G$13:G$62,MATCH(6-COUNTIFS('New Tooling Jobs'!A$13:A$62,"<>",'New Tooling Jobs'!E$13:E$62,"<>Completed"),Reorders!AC$13:AC$62,0))),"") | F15: =IFERROR(IF(6<=COUNTIFS('New Tooling Jobs'!A$13:A$62,"<>",'New Tooling Jobs'!E$13:E$62,"<>Completed"),INDEX('New Tooling Jobs'!H$13:H$62,MATCH(6,'New Tooling Jobs'!AG$13:AG$62,0)),INDEX(Reorders!H$13:H$62,MATCH(6-COUNTIFS('New Tooling Jobs'!A$13:A$62,"<>",'New Tooling Jobs'!E$13:E$62,"<>Completed"),Reorders!AC$13:AC$62,0))),"") | G15: =IFERROR(IF(6<=COUNTIFS('New Tooling Jobs'!A$13:A$62,"<>",'New Tooling Jobs'!E$13:E$62,"<>Completed"),INDEX('New Tooling Jobs'!I$13:I$62,MATCH(6,'New Tooling Jobs'!AG$13:AG$62,0)),INDEX(Reorders!I$13:I$62,MATCH(6-COUNTIFS('New Tooling Jobs'!A$13:A$62,"<>",'New Tooling Jobs'!E$13:E$62,"<>Completed"),Reorders!AC$13:AC$62,0))),"")
A16: =IFERROR(IF(7<=COUNTIFS('New Tooling Jobs'!A$13:A$62,"<>",'New Tooling Jobs'!E$13:E$62,"<>Completed"),INDEX('New Tooling Jobs'!A$13:A$62,MATCH(7,'New Tooling Jobs'!AG$13:AG$62,0)),INDEX(Reorders!A$13:A$62,MATCH(7-COUNTIFS('New Tooling Jobs'!A$13:A$62,"<>",'New Tooling Jobs'!E$13:E$62,"<>Completed"),Reorders!AC$13:AC$62,0))),"") | B16: =IFERROR(IF(7<=COUNTIFS('New Tooling Jobs'!A$13:A$62,"<>",'New Tooling Jobs'!E$13:E$62,"<>Completed"),IF(INDEX('New Tooling Jobs'!A$13:A$62,MATCH(7,'New Tooling Jobs'!AG$13:AG$62,0))<>"","New Tooling",""),IF(INDEX(Reorders!A$13:A$62,MATCH(7-COUNTIFS('New Tooling Jobs'!A$13:A$62,"<>",'New Tooling Jobs'!E$13:E$62,"<>Completed"),Reorders!AC$13:AC$62,0))<>"","Reorder","")),"") | C16: =IFERROR(IF(7<=COUNTIFS('New Tooling Jobs'!A$13:A$62,"<>",'New Tooling Jobs'!E$13:E$62,"<>Completed"),INDEX('New Tooling Jobs'!B$13:B$62,MATCH(7,'New Tooling Jobs'!AG$13:AG$62,0)),INDEX(Reorders!B$13:B$62,MATCH(7-COUNTIFS('New Tooling Jobs'!A$13:A$62,"<>",'New Tooling Jobs'!E$13:E$62,"<>Completed"),Reorders!AC$13:AC$62,0))),"") | D16: =IFERROR(IF(7<=COUNTIFS('New Tooling Jobs'!A$13:A$62,"<>",'New Tooling Jobs'!E$13:E$62,"<>Completed"),INDEX('New Tooling Jobs'!E$13:E$62,MATCH(7,'New Tooling Jobs'!AG$13:AG$62,0)),INDEX(Reorders!E$13:E$62,MATCH(7-COUNTIFS('New Tooling Jobs'!A$13:A$62,"<>",'New Tooling Jobs'!E$13:E$62,"<>Completed"),Reorders!AC$13:AC$62,0))),"") | E16: =IFERROR(IF(7<=COUNTIFS('New Tooling Jobs'!A$13:A$62,"<>",'New Tooling Jobs'!E$13:E$62,"<>Completed"),INDEX('New Tooling Jobs'!G$13:G$62,MATCH(7,'New Tooling Jobs'!AG$13:AG$62,0)),INDEX(Reorders!G$13:G$62,MATCH(7-COUNTIFS('New Tooling Jobs'!A$13:A$62,"<>",'New Tooling Jobs'!E$13:E$62,"<>Completed"),Reorders!AC$13:AC$62,0))),"") | F16: =IFERROR(IF(7<=COUNTIFS('New Tooling Jobs'!A$13:A$62,"<>",'New Tooling Jobs'!E$13:E$62,"<>Completed"),INDEX('New Tooling Jobs'!H$13:H$62,MATCH(7,'New Tooling Jobs'!AG$13:AG$62,0)),INDEX(Reorders!H$13:H$62,MATCH(7-COUNTIFS('New Tooling Jobs'!A$13:A$62,"<>",'New Tooling Jobs'!E$13:E$62,"<>Completed"),Reorders!AC$13:AC$62,0))),"") | G16: =IFERROR(IF(7<=COUNTIFS('New Tooling Jobs'!A$13:A$62,"<>",'New Tooling Jobs'!E$13:E$62,"<>Completed"),INDEX('New Tooling Jobs'!I$13:I$62,MATCH(7,'New Tooling Jobs'!AG$13:AG$62,0)),INDEX(Reorders!I$13:I$62,MATCH(7-COUNTIFS('New Tooling Jobs'!A$13:A$62,"<>",'New Tooling Jobs'!E$13:E$62,"<>Completed"),Reorders!AC$13:AC$62,0))),"")
A17: =IFERROR(IF(8<=COUNTIFS('New Tooling Jobs'!A$13:A$62,"<>",'New Tooling Jobs'!E$13:E$62,"<>Completed"),INDEX('New Tooling Jobs'!A$13:A$62,MATCH(8,'New Tooling Jobs'!AG$13:AG$62,0)),INDEX(Reorders!A$13:A$62,MATCH(8-COUNTIFS('New Tooling Jobs'!A$13:A$62,"<>",'New Tooling Jobs'!E$13:E$62,"<>Completed"),Reorders!AC$13:AC$62,0))),"") | B17: =IFERROR(IF(8<=COUNTIFS('New Tooling Jobs'!A$13:A$62,"<>",'New Tooling Jobs'!E$13:E$62,"<>Completed"),IF(INDEX('New Tooling Jobs'!A$13:A$62,MATCH(8,'New Tooling Jobs'!AG$13:AG$62,0))<>"","New Tooling",""),IF(INDEX(Reorders!A$13:A$62,MATCH(8-COUNTIFS('New Tooling Jobs'!A$13:A$62,"<>",'New Tooling Jobs'!E$13:E$62,"<>Completed"),Reorders!AC$13:AC$62,0))<>"","Reorder","")),"") | C17: =IFERROR(IF(8<=COUNTIFS('New Tooling Jobs'!A$13:A$62,"<>",'New Tooling Jobs'!E$13:E$62,"<>Completed"),INDEX('New Tooling Jobs'!B$13:B$62,MATCH(8,'New Tooling Jobs'!AG$13:AG$62,0)),INDEX(Reorders!B$13:B$62,MATCH(8-COUNTIFS('New Tooling Jobs'!A$13:A$62,"<>",'New Tooling Jobs'!E$13:E$62,"<>Completed"),Reorders!AC$13:AC$62,0))),"") | D17: =IFERROR(IF(8<=COUNTIFS('New Tooling Jobs'!A$13:A$62,"<>",'New Tooling Jobs'!E$13:E$62,"<>Completed"),INDEX('New Tooling Jobs'!E$13:E$62,MATCH(8,'New Tooling Jobs'!AG$13:AG$62,0)),INDEX(Reorders!E$13:E$62,MATCH(8-COUNTIFS('New Tooling Jobs'!A$13:A$62,"<>",'New Tooling Jobs'!E$13:E$62,"<>Completed"),Reorders!AC$13:AC$62,0))),"") | E17: =IFERROR(IF(8<=COUNTIFS('New Tooling Jobs'!A$13:A$62,"<>",'New Tooling Jobs'!E$13:E$62,"<>Completed"),INDEX('New Tooling Jobs'!G$13:G$62,MATCH(8,'New Tooling Jobs'!AG$13:AG$62,0)),INDEX(Reorders!G$13:G$62,MATCH(8-COUNTIFS('New Tooling Jobs'!A$13:A$62,"<>",'New Tooling Jobs'!E$13:E$62,"<>Completed"),Reorders!AC$13:AC$62,0))),"") | F17: =IFERROR(IF(8<=COUNTIFS('New Tooling Jobs'!A$13:A$62,"<>",'New Tooling Jobs'!E$13:E$62,"<>Completed"),INDEX('New Tooling Jobs'!H$13:H$62,MATCH(8,'New Tooling Jobs'!AG$13:AG$62,0)),INDEX(Reorders!H$13:H$62,MATCH(8-COUNTIFS('New Tooling Jobs'!A$13:A$62,"<>",'New Tooling Jobs'!E$13:E$62,"<>Completed"),Reorders!AC$13:AC$62,0))),"") | G17: =IFERROR(IF(8<=COUNTIFS('New Tooling Jobs'!A$13:A$62,"<>",'New Tooling Jobs'!E$13:E$62,"<>Completed"),INDEX('New Tooling Jobs'!I$13:I$62,MATCH(8,'New Tooling Jobs'!AG$13:AG$62,0)),INDEX(Reorders!I$13:I$62,MATCH(8-COUNTIFS('New Tooling Jobs'!A$13:A$62,"<>",'New Tooling Jobs'!E$13:E$62,"<>Completed"),Reorders!AC$13:AC$62,0))),"")
A18: =IFERROR(IF(9<=COUNTIFS('New Tooling Jobs'!A$13:A$62,"<>",'New Tooling Jobs'!E$13:E$62,"<>Completed"),INDEX('New Tooling Jobs'!A$13:A$62,MATCH(9,'New Tooling Jobs'!AG$13:AG$62,0)),INDEX(Reorders!A$13:A$62,MATCH(9-COUNTIFS('New Tooling Jobs'!A$13:A$62,"<>",'New Tooling Jobs'!E$13:E$62,"<>Completed"),Reorders!AC$13:AC$62,0))),"") | B18: =IFERROR(IF(9<=COUNTIFS('New Tooling Jobs'!A$13:A$62,"<>",'New Tooling Jobs'!E$13:E$62,"<>Completed"),IF(INDEX('New Tooling Jobs'!A$13:A$62,MATCH(9,'New Tooling Jobs'!AG$13:AG$62,0))<>"","New Tooling",""),IF(INDEX(Reorders!A$13:A$62,MATCH(9-COUNTIFS('New Tooling Jobs'!A$13:A$62,"<>",'New Tooling Jobs'!E$13:E$62,"<>Completed"),Reorders!AC$13:AC$62,0))<>"","Reorder","")),"") | C18: =IFERROR(IF(9<=COUNTIFS('New Tooling Jobs'!A$13:A$62,"<>",'New Tooling Jobs'!E$13:E$62,"<>Completed"),INDEX('New Tooling Jobs'!B$13:B$62,MATCH(9,'New Tooling Jobs'!AG$13:AG$62,0)),INDEX(Reorders!B$13:B$62,MATCH(9-COUNTIFS('New Tooling Jobs'!A$13:A$62,"<>",'New Tooling Jobs'!E$13:E$62,"<>Completed"),Reorders!AC$13:AC$62,0))),"") | D18: =IFERROR(IF(9<=COUNTIFS('New Tooling Jobs'!A$13:A$62,"<>",'New Tooling Jobs'!E$13:E$62,"<>Completed"),INDEX('New Tooling Jobs'!E$13:E$62,MATCH(9,'New Tooling Jobs'!AG$13:AG$62,0)),INDEX(Reorders!E$13:E$62,MATCH(9-COUNTIFS('New Tooling Jobs'!A$13:A$62,"<>",'New Tooling Jobs'!E$13:E$62,"<>Completed"),Reorders!AC$13:AC$62,0))),"") | E18: =IFERROR(IF(9<=COUNTIFS('New Tooling Jobs'!A$13:A$62,"<>",'New Tooling Jobs'!E$13:E$62,"<>Completed"),INDEX('New Tooling Jobs'!G$13:G$62,MATCH(9,'New Tooling Jobs'!AG$13:AG$62,0)),INDEX(Reorders!G$13:G$62,MATCH(9-COUNTIFS('New Tooling Jobs'!A$13:A$62,"<>",'New Tooling Jobs'!E$13:E$62,"<>Completed"),Reorders!AC$13:AC$62,0))),"") | F18: =IFERROR(IF(9<=COUNTIFS('New Tooling Jobs'!A$13:A$62,"<>",'New Tooling Jobs'!E$13:E$62,"<>Completed"),INDEX('New Tooling Jobs'!H$13:H$62,MATCH(9,'New Tooling Jobs'!AG$13:AG$62,0)),INDEX(Reorders!H$13:H$62,MATCH(9-COUNTIFS('New Tooling Jobs'!A$13:A$62,"<>",'New Tooling Jobs'!E$13:E$62,"<>Completed"),Reorders!AC$13:AC$62,0))),"") | G18: =IFERROR(IF(9<=COUNTIFS('New Tooling Jobs'!A$13:A$62,"<>",'New Tooling Jobs'!E$13:E$62,"<>Completed"),INDEX('New Tooling Jobs'!I$13:I$62,MATCH(9,'New Tooling Jobs'!AG$13:AG$62,0)),INDEX(Reorders!I$13:I$62,MATCH(9-COUNTIFS('New Tooling Jobs'!A$13:A$62,"<>",'New Tooling Jobs'!E$13:E$62,"<>Completed"),Reorders!AC$13:AC$62,0))),"")
A19: =IFERROR(IF(10<=COUNTIFS('New Tooling Jobs'!A$13:A$62,"<>",'New Tooling Jobs'!E$13:E$62,"<>Completed"),INDEX('New Tooling Jobs'!A$13:A$62,MATCH(10,'New Tooling Jobs'!AG$13:AG$62,0)),INDEX(Reorders!A$13:A$62,MATCH(10-COUNTIFS('New Tooling Jobs'!A$13:A$62,"<>",'New Tooling Jobs'!E$13:E$62,"<>Completed"),Reorders!AC$13:AC$62,0))),"") | B19: =IFERROR(IF(10<=COUNTIFS('New Tooling Jobs'!A$13:A$62,"<>",'New Tooling Jobs'!E$13:E$62,"<>Completed"),IF(INDEX('New Tooling Jobs'!A$13:A$62,MATCH(10,'New Tooling Jobs'!AG$13:AG$62,0))<>"","New Tooling",""),IF(INDEX(Reorders!A$13:A$62,MATCH(10-COUNTIFS('New Tooling Jobs'!A$13:A$62,"<>",'New Tooling Jobs'!E$13:E$62,"<>Completed"),Reorders!AC$13:AC$62,0))<>"","Reorder","")),"") | C19: =IFERROR(IF(10<=COUNTIFS('New Tooling Jobs'!A$13:A$62,"<>",'New Tooling Jobs'!E$13:E$62,"<>Completed"),INDEX('New Tooling Jobs'!B$13:B$62,MATCH(10,'New Tooling Jobs'!AG$13:AG$62,0)),INDEX(Reorders!B$13:B$62,MATCH(10-COUNTIFS('New Tooling Jobs'!A$13:A$62,"<>",'New Tooling Jobs'!E$13:E$62,"<>Completed"),Reorders!AC$13:AC$62,0))),"") | D19: =IFERROR(IF(10<=COUNTIFS('New Tooling Jobs'!A$13:A$62,"<>",'New Tooling Jobs'!E$13:E$62,"<>Completed"),INDEX('New Tooling Jobs'!E$13:E$62,MATCH(10,'New Tooling Jobs'!AG$13:AG$62,0)),INDEX(Reorders!E$13:E$62,MATCH(10-COUNTIFS('New Tooling Jobs'!A$13:A$62,"<>",'New Tooling Jobs'!E$13:E$62,"<>Completed"),Reorders!AC$13:AC$62,0))),"") | E19: =IFERROR(IF(10<=COUNTIFS('New Tooling Jobs'!A$13:A$62,"<>",'New Tooling Jobs'!E$13:E$62,"<>Completed"),INDEX('New Tooling Jobs'!G$13:G$62,MATCH(10,'New Tooling Jobs'!AG$13:AG$62,0)),INDEX(Reorders!G$13:G$62,MATCH(10-COUNTIFS('New Tooling Jobs'!A$13:A$62,"<>",'New Tooling Jobs'!E$13:E$62,"<>Completed"),Reorders!AC$13:AC$62,0))),"") | F19: =IFERROR(IF(10<=COUNTIFS('New Tooling Jobs'!A$13:A$62,"<>",'New Tooling Jobs'!E$13:E$62,"<>Completed"),INDEX('New Tooling Jobs'!H$13:H$62,MATCH(10,'New Tooling Jobs'!AG$13:AG$62,0)),INDEX(Reorders!H$13:H$62,MATCH(10-COUNTIFS('New Tooling Jobs'!A$13:A$62,"<>",'New Tooling Jobs'!E$13:E$62,"<>Completed"),Reorders!AC$13:AC$62,0))),"") | G19: =IFERROR(IF(10<=COUNTIFS('New Tooling Jobs'!A$13:A$62,"<>",'New Tooling Jobs'!E$13:E$62,"<>Completed"),INDEX('New Tooling Jobs'!I$13:I$62,MATCH(10,'New Tooling Jobs'!AG$13:AG$62,0)),INDEX(Reorders!I$13:I$62,MATCH(10-COUNTIFS('New Tooling Jobs'!A$13:A$62,"<>",'New Tooling Jobs'!E$13:E$62,"<>Completed"),Reorders!AC$13:AC$62,0))),"")
A20: =IFERROR(IF(11<=COUNTIFS('New Tooling Jobs'!A$13:A$62,"<>",'New Tooling Jobs'!E$13:E$62,"<>Completed"),INDEX('New Tooling Jobs'!A$13:A$62,MATCH(11,'New Tooling Jobs'!AG$13:AG$62,0)),INDEX(Reorders!A$13:A$62,MATCH(11-COUNTIFS('New Tooling Jobs'!A$13:A$62,"<>",'New Tooling Jobs'!E$13:E$62,"<>Completed"),Reorders!AC$13:AC$62,0))),"") | B20: =IFERROR(IF(11<=COUNTIFS('New Tooling Jobs'!A$13:A$62,"<>",'New Tooling Jobs'!E$13:E$62,"<>Completed"),IF(INDEX('New Tooling Jobs'!A$13:A$62,MATCH(11,'New Tooling Jobs'!AG$13:AG$62,0))<>"","New Tooling",""),IF(INDEX(Reorders!A$13:A$62,MATCH(11-COUNTIFS('New Tooling Jobs'!A$13:A$62,"<>",'New Tooling Jobs'!E$13:E$62,"<>Completed"),Reorders!AC$13:AC$62,0))<>"","Reorder","")),"") | C20: =IFERROR(IF(11<=COUNTIFS('New Tooling Jobs'!A$13:A$62,"<>",'New Tooling Jobs'!E$13:E$62,"<>Completed"),INDEX('New Tooling Jobs'!B$13:B$62,MATCH(11,'New Tooling Jobs'!AG$13:AG$62,0)),INDEX(Reorders!B$13:B$62,MATCH(11-COUNTIFS('New Tooling Jobs'!A$13:A$62,"<>",'New Tooling Jobs'!E$13:E$62,"<>Completed"),Reorders!AC$13:AC$62,0))),"") | D20: =IFERROR(IF(11<=COUNTIFS('New Tooling Jobs'!A$13:A$62,"<>",'New Tooling Jobs'!E$13:E$62,"<>Completed"),INDEX('New Tooling Jobs'!E$13:E$62,MATCH(11,'New Tooling Jobs'!AG$13:AG$62,0)),INDEX(Reorders!E$13:E$62,MATCH(11-COUNTIFS('New Tooling Jobs'!A$13:A$62,"<>",'New Tooling Jobs'!E$13:E$62,"<>Completed"),Reorders!AC$13:AC$62,0))),"") | E20: =IFERROR(IF(11<=COUNTIFS('New Tooling Jobs'!A$13:A$62,"<>",'New Tooling Jobs'!E$13:E$62,"<>Completed"),INDEX('New Tooling Jobs'!G$13:G$62,MATCH(11,'New Tooling Jobs'!AG$13:AG$62,0)),INDEX(Reorders!G$13:G$62,MATCH(11-COUNTIFS('New Tooling Jobs'!A$13:A$62,"<>",'New Tooling Jobs'!E$13:E$62,"<>Completed"),Reorders!AC$13:AC$62,0))),"") | F20: =IFERROR(IF(11<=COUNTIFS('New Tooling Jobs'!A$13:A$62,"<>",'New Tooling Jobs'!E$13:E$62,"<>Completed"),INDEX('New Tooling Jobs'!H$13:H$62,MATCH(11,'New Tooling Jobs'!AG$13:AG$62,0)),INDEX(Reorders!H$13:H$62,MATCH(11-COUNTIFS('New Tooling Jobs'!A$13:A$62,"<>",'New Tooling Jobs'!E$13:E$62,"<>Completed"),Reorders!AC$13:AC$62,0))),"") | G20: =IFERROR(IF(11<=COUNTIFS('New Tooling Jobs'!A$13:A$62,"<>",'New Tooling Jobs'!E$13:E$62,"<>Completed"),INDEX('New Tooling Jobs'!I$13:I$62,MATCH(11,'New Tooling Jobs'!AG$13:AG$62,0)),INDEX(Reorders!I$13:I$62,MATCH(11-COUNTIFS('New Tooling Jobs'!A$13:A$62,"<>",'New Tooling Jobs'!E$13:E$62,"<>Completed"),Reorders!AC$13:AC$62,0))),"")
A21: =IFERROR(IF(12<=COUNTIFS('New Tooling Jobs'!A$13:A$62,"<>",'New Tooling Jobs'!E$13:E$62,"<>Completed"),INDEX('New Tooling Jobs'!A$13:A$62,MATCH(12,'New Tooling Jobs'!AG$13:AG$62,0)),INDEX(Reorders!A$13:A$62,MATCH(12-COUNTIFS('New Tooling Jobs'!A$13:A$62,"<>",'New Tooling Jobs'!E$13:E$62,"<>Completed"),Reorders!AC$13:AC$62,0))),"") | B21: =IFERROR(IF(12<=COUNTIFS('New Tooling Jobs'!A$13:A$62,"<>",'New Tooling Jobs'!E$13:E$62,"<>Completed"),IF(INDEX('New Tooling Jobs'!A$13:A$62,MATCH(12,'New Tooling Jobs'!AG$13:AG$62,0))<>"","New Tooling",""),IF(INDEX(Reorders!A$13:A$62,MATCH(12-COUNTIFS('New Tooling Jobs'!A$13:A$62,"<>",'New Tooling Jobs'!E$13:E$62,"<>Completed"),Reorders!AC$13:AC$62,0))<>"","Reorder","")),"") | C21: =IFERROR(IF(12<=COUNTIFS('New Tooling Jobs'!A$13:A$62,"<>",'New Tooling Jobs'!E$13:E$62,"<>Completed"),INDEX('New Tooling Jobs'!B$13:B$62,MATCH(12,'New Tooling Jobs'!AG$13:AG$62,0)),INDEX(Reorders!B$13:B$62,MATCH(12-COUNTIFS('New Tooling Jobs'!A$13:A$62,"<>",'New Tooling Jobs'!E$13:E$62,"<>Completed"),Reorders!AC$13:AC$62,0))),"") | D21: =IFERROR(IF(12<=COUNTIFS('New Tooling Jobs'!A$13:A$62,"<>",'New Tooling Jobs'!E$13:E$62,"<>Completed"),INDEX('New Tooling Jobs'!E$13:E$62,MATCH(12,'New Tooling Jobs'!AG$13:AG$62,0)),INDEX(Reorders!E$13:E$62,MATCH(12-COUNTIFS('New Tooling Jobs'!A$13:A$62,"<>",'New Tooling Jobs'!E$13:E$62,"<>Completed"),Reorders!AC$13:AC$62,0))),"") | E21: =IFERROR(IF(12<=COUNTIFS('New Tooling Jobs'!A$13:A$62,"<>",'New Tooling Jobs'!E$13:E$62,"<>Completed"),INDEX('New Tooling Jobs'!G$13:G$62,MATCH(12,'New Tooling Jobs'!AG$13:AG$62,0)),INDEX(Reorders!G$13:G$62,MATCH(12-COUNTIFS('New Tooling Jobs'!A$13:A$62,"<>",'New Tooling Jobs'!E$13:E$62,"<>Completed"),Reorders!AC$13:AC$62,0))),"") | F21: =IFERROR(IF(12<=COUNTIFS('New Tooling Jobs'!A$13:A$62,"<>",'New Tooling Jobs'!E$13:E$62,"<>Completed"),INDEX('New Tooling Jobs'!H$13:H$62,MATCH(12,'New Tooling Jobs'!AG$13:AG$62,0)),INDEX(Reorders!H$13:H$62,MATCH(12-COUNTIFS('New Tooling Jobs'!A$13:A$62,"<>",'New Tooling Jobs'!E$13:E$62,"<>Completed"),Reorders!AC$13:AC$62,0))),"") | G21: =IFERROR(IF(12<=COUNTIFS('New Tooling Jobs'!A$13:A$62,"<>",'New Tooling Jobs'!E$13:E$62,"<>Completed"),INDEX('New Tooling Jobs'!I$13:I$62,MATCH(12,'New Tooling Jobs'!AG$13:AG$62,0)),INDEX(Reorders!I$13:I$62,MATCH(12-COUNTIFS('New Tooling Jobs'!A$13:A$62,"<>",'New Tooling Jobs'!E$13:E$62,"<>Completed"),Reorders!AC$13:AC$62,0))),"")
A22: =IFERROR(IF(13<=COUNTIFS('New Tooling Jobs'!A$13:A$62,"<>",'New Tooling Jobs'!E$13:E$62,"<>Completed"),INDEX('New Tooling Jobs'!A$13:A$62,MATCH(13,'New Tooling Jobs'!AG$13:AG$62,0)),INDEX(Reorders!A$13:A$62,MATCH(13-COUNTIFS('New Tooling Jobs'!A$13:A$62,"<>",'New Tooling Jobs'!E$13:E$62,"<>Completed"),Reorders!AC$13:AC$62,0))),"") | B22: =IFERROR(IF(13<=COUNTIFS('New Tooling Jobs'!A$13:A$62,"<>",'New Tooling Jobs'!E$13:E$62,"<>Completed"),IF(INDEX('New Tooling Jobs'!A$13:A$62,MATCH(13,'New Tooling Jobs'!AG$13:AG$62,0))<>"","New Tooling",""),IF(INDEX(Reorders!A$13:A$62,MATCH(13-COUNTIFS('New Tooling Jobs'!A$13:A$62,"<>",'New Tooling Jobs'!E$13:E$62,"<>Completed"),Reorders!AC$13:AC$62,0))<>"","Reorder","")),"") | C22: =IFERROR(IF(13<=COUNTIFS('New Tooling Jobs'!A$13:A$62,"<>",'New Tooling Jobs'!E$13:E$62,"<>Completed"),INDEX('New Tooling Jobs'!B$13:B$62,MATCH(13,'New Tooling Jobs'!AG$13:AG$62,0)),INDEX(Reorders!B$13:B$62,MATCH(13-COUNTIFS('New Tooling Jobs'!A$13:A$62,"<>",'New Tooling Jobs'!E$13:E$62,"<>Completed"),Reorders!AC$13:AC$62,0))),"") | D22: =IFERROR(IF(13<=COUNTIFS('New Tooling Jobs'!A$13:A$62,"<>",'New Tooling Jobs'!E$13:E$62,"<>Completed"),INDEX('New Tooling Jobs'!E$13:E$62,MATCH(13,'New Tooling Jobs'!AG$13:AG$62,0)),INDEX(Reorders!E$13:E$62,MATCH(13-COUNTIFS('New Tooling Jobs'!A$13:A$62,"<>",'New Tooling Jobs'!E$13:E$62,"<>Completed"),Reorders!AC$13:AC$62,0))),"") | E22: =IFERROR(IF(13<=COUNTIFS('New Tooling Jobs'!A$13:A$62,"<>",'New Tooling Jobs'!E$13:E$62,"<>Completed"),INDEX('New Tooling Jobs'!G$13:G$62,MATCH(13,'New Tooling Jobs'!AG$13:AG$62,0)),INDEX(Reorders!G$13:G$62,MATCH(13-COUNTIFS('New Tooling Jobs'!A$13:A$62,"<>",'New Tooling Jobs'!E$13:E$62,"<>Completed"),Reorders!AC$13:AC$62,0))),"") | F22: =IFERROR(IF(13<=COUNTIFS('New Tooling Jobs'!A$13:A$62,"<>",'New Tooling Jobs'!E$13:E$62,"<>Completed"),INDEX('New Tooling Jobs'!H$13:H$62,MATCH(13,'New Tooling Jobs'!AG$13:AG$62,0)),INDEX(Reorders!H$13:H$62,MATCH(13-COUNTIFS('New Tooling Jobs'!A$13:A$62,"<>",'New Tooling Jobs'!E$13:E$62,"<>Completed"),Reorders!AC$13:AC$62,0))),"") | G22: =IFERROR(IF(13<=COUNTIFS('New Tooling Jobs'!A$13:A$62,"<>",'New Tooling Jobs'!E$13:E$62,"<>Completed"),INDEX('New Tooling Jobs'!I$13:I$62,MATCH(13,'New Tooling Jobs'!AG$13:AG$62,0)),INDEX(Reorders!I$13:I$62,MATCH(13-COUNTIFS('New Tooling Jobs'!A$13:A$62,"<>",'New Tooling Jobs'!E$13:E$62,"<>Completed"),Reorders!AC$13:AC$62,0))),"")
A23: =IFERROR(IF(14<=COUNTIFS('New Tooling Jobs'!A$13:A$62,"<>",'New Tooling Jobs'!E$13:E$62,"<>Completed"),INDEX('New Tooling Jobs'!A$13:A$62,MATCH(14,'New Tooling Jobs'!AG$13:AG$62,0)),INDEX(Reorders!A$13:A$62,MATCH(14-COUNTIFS('New Tooling Jobs'!A$13:A$62,"<>",'New Tooling Jobs'!E$13:E$62,"<>Completed"),Reorders!AC$13:AC$62,0))),"") | B23: =IFERROR(IF(14<=COUNTIFS('New Tooling Jobs'!A$13:A$62,"<>",'New Tooling Jobs'!E$13:E$62,"<>Completed"),IF(INDEX('New Tooling Jobs'!A$13:A$62,MATCH(14,'New Tooling Jobs'!AG$13:AG$62,0))<>"","New Tooling",""),IF(INDEX(Reorders!A$13:A$62,MATCH(14-COUNTIFS('New Tooling Jobs'!A$13:A$62,"<>",'New Tooling Jobs'!E$13:E$62,"<>Completed"),Reorders!AC$13:AC$62,0))<>"","Reorder","")),"") | C23: =IFERROR(IF(14<=COUNTIFS('New Tooling Jobs'!A$13:A$62,"<>",'New Tooling Jobs'!E$13:E$62,"<>Completed"),INDEX('New Tooling Jobs'!B$13:B$62,MATCH(14,'New Tooling Jobs'!AG$13:AG$62,0)),INDEX(Reorders!B$13:B$62,MATCH(14-COUNTIFS('New Tooling Jobs'!A$13:A$62,"<>",'New Tooling Jobs'!E$13:E$62,"<>Completed"),Reorders!AC$13:AC$62,0))),"") | D23: =IFERROR(IF(14<=COUNTIFS('New Tooling Jobs'!A$13:A$62,"<>",'New Tooling Jobs'!E$13:E$62,"<>Completed"),INDEX('New Tooling Jobs'!E$13:E$62,MATCH(14,'New Tooling Jobs'!AG$13:AG$62,0)),INDEX(Reorders!E$13:E$62,MATCH(14-COUNTIFS('New Tooling Jobs'!A$13:A$62,"<>",'New Tooling Jobs'!E$13:E$62,"<>Completed"),Reorders!AC$13:AC$62,0))),"") | E23: =IFERROR(IF(14<=COUNTIFS('New Tooling Jobs'!A$13:A$62,"<>",'New Tooling Jobs'!E$13:E$62,"<>Completed"),INDEX('New Tooling Jobs'!G$13:G$62,MATCH(14,'New Tooling Jobs'!AG$13:AG$62,0)),INDEX(Reorders!G$13:G$62,MATCH(14-COUNTIFS('New Tooling Jobs'!A$13:A$62,"<>",'New Tooling Jobs'!E$13:E$62,"<>Completed"),Reorders!AC$13:AC$62,0))),"") | F23: =IFERROR(IF(14<=COUNTIFS('New Tooling Jobs'!A$13:A$62,"<>",'New Tooling Jobs'!E$13:E$62,"<>Completed"),INDEX('New Tooling Jobs'!H$13:H$62,MATCH(14,'New Tooling Jobs'!AG$13:AG$62,0)),INDEX(Reorders!H$13:H$62,MATCH(14-COUNTIFS('New Tooling Jobs'!A$13:A$62,"<>",'New Tooling Jobs'!E$13:E$62,"<>Completed"),Reorders!AC$13:AC$62,0))),"") | G23: =IFERROR(IF(14<=COUNTIFS('New Tooling Jobs'!A$13:A$62,"<>",'New Tooling Jobs'!E$13:E$62,"<>Completed"),INDEX('New Tooling Jobs'!I$13:I$62,MATCH(14,'New Tooling Jobs'!AG$13:AG$62,0)),INDEX(Reorders!I$13:I$62,MATCH(14-COUNTIFS('New Tooling Jobs'!A$13:A$62,"<>",'New Tooling Jobs'!E$13:E$62,"<>Completed"),Reorders!AC$13:AC$62,0))),"")
A24: =IFERROR(IF(15<=COUNTIFS('New Tooling Jobs'!A$13:A$62,"<>",'New Tooling Jobs'!E$13:E$62,"<>Completed"),INDEX('New Tooling Jobs'!A$13:A$62,MATCH(15,'New Tooling Jobs'!AG$13:AG$62,0)),INDEX(Reorders!A$13:A$62,MATCH(15-COUNTIFS('New Tooling Jobs'!A$13:A$62,"<>",'New Tooling Jobs'!E$13:E$62,"<>Completed"),Reorders!AC$13:AC$62,0))),"") | B24: =IFERROR(IF(15<=COUNTIFS('New Tooling Jobs'!A$13:A$62,"<>",'New Tooling Jobs'!E$13:E$62,"<>Completed"),IF(INDEX('New Tooling Jobs'!A$13:A$62,MATCH(15,'New Tooling Jobs'!AG$13:AG$62,0))<>"","New Tooling",""),IF(INDEX(Reorders!A$13:A$62,MATCH(15-COUNTIFS('New Tooling Jobs'!A$13:A$62,"<>",'New Tooling Jobs'!E$13:E$62,"<>Completed"),Reorders!AC$13:AC$62,0))<>"","Reorder","")),"") | C24: =IFERROR(IF(15<=COUNTIFS('New Tooling Jobs'!A$13:A$62,"<>",'New Tooling Jobs'!E$13:E$62,"<>Completed"),INDEX('New Tooling Jobs'!B$13:B$62,MATCH(15,'New Tooling Jobs'!AG$13:AG$62,0)),INDEX(Reorders!B$13:B$62,MATCH(15-COUNTIFS('New Tooling Jobs'!A$13:A$62,"<>",'New Tooling Jobs'!E$13:E$62,"<>Completed"),Reorders!AC$13:AC$62,0))),"") | D24: =IFERROR(IF(15<=COUNTIFS('New Tooling Jobs'!A$13:A$62,"<>",'New Tooling Jobs'!E$13:E$62,"<>Completed"),INDEX('New Tooling Jobs'!E$13:E$62,MATCH(15,'New Tooling Jobs'!AG$13:AG$62,0)),INDEX(Reorders!E$13:E$62,MATCH(15-COUNTIFS('New Tooling Jobs'!A$13:A$62,"<>",'New Tooling Jobs'!E$13:E$62,"<>Completed"),Reorders!AC$13:AC$62,0))),"") | E24: =IFERROR(IF(15<=COUNTIFS('New Tooling Jobs'!A$13:A$62,"<>",'New Tooling Jobs'!E$13:E$62,"<>Completed"),INDEX('New Tooling Jobs'!G$13:G$62,MATCH(15,'New Tooling Jobs'!AG$13:AG$62,0)),INDEX(Reorders!G$13:G$62,MATCH(15-COUNTIFS('New Tooling Jobs'!A$13:A$62,"<>",'New Tooling Jobs'!E$13:E$62,"<>Completed"),Reorders!AC$13:AC$62,0))),"") | F24: =IFERROR(IF(15<=COUNTIFS('New Tooling Jobs'!A$13:A$62,"<>",'New Tooling Jobs'!E$13:E$62,"<>Completed"),INDEX('New Tooling Jobs'!H$13:H$62,MATCH(15,'New Tooling Jobs'!AG$13:AG$62,0)),INDEX(Reorders!H$13:H$62,MATCH(15-COUNTIFS('New Tooling Jobs'!A$13:A$62,"<>",'New Tooling Jobs'!E$13:E$62,"<>Completed"),Reorders!AC$13:AC$62,0))),"") | G24: =IFERROR(IF(15<=COUNTIFS('New Tooling Jobs'!A$13:A$62,"<>",'New Tooling Jobs'!E$13:E$62,"<>Completed"),INDEX('New Tooling Jobs'!I$13:I$62,MATCH(15,'New Tooling Jobs'!AG$13:AG$62,0)),INDEX(Reorders!I$13:I$62,MATCH(15-COUNTIFS('New Tooling Jobs'!A$13:A$62,"<>",'New Tooling Jobs'!E$13:E$62,"<>Completed"),Reorders!AC$13:AC$62,0))),"")
A25: =IFERROR(IF(16<=COUNTIFS('New Tooling Jobs'!A$13:A$62,"<>",'New Tooling Jobs'!E$13:E$62,"<>Completed"),INDEX('New Tooling Jobs'!A$13:A$62,MATCH(16,'New Tooling Jobs'!AG$13:AG$62,0)),INDEX(Reorders!A$13:A$62,MATCH(16-COUNTIFS('New Tooling Jobs'!A$13:A$62,"<>",'New Tooling Jobs'!E$13:E$62,"<>Completed"),Reorders!AC$13:AC$62,0))),"") | B25: =IFERROR(IF(16<=COUNTIFS('New Tooling Jobs'!A$13:A$62,"<>",'New Tooling Jobs'!E$13:E$62,"<>Completed"),IF(INDEX('New Tooling Jobs'!A$13:A$62,MATCH(16,'New Tooling Jobs'!AG$13:AG$62,0))<>"","New Tooling",""),IF(INDEX(Reorders!A$13:A$62,MATCH(16-COUNTIFS('New Tooling Jobs'!A$13:A$62,"<>",'New Tooling Jobs'!E$13:E$62,"<>Completed"),Reorders!AC$13:AC$62,0))<>"","Reorder","")),"") | C25: =IFERROR(IF(16<=COUNTIFS('New Tooling Jobs'!A$13:A$62,"<>",'New Tooling Jobs'!E$13:E$62,"<>Completed"),INDEX('New Tooling Jobs'!B$13:B$62,MATCH(16,'New Tooling Jobs'!AG$13:AG$62,0)),INDEX(Reorders!B$13:B$62,MATCH(16-COUNTIFS('New Tooling Jobs'!A$13:A$62,"<>",'New Tooling Jobs'!E$13:E$62,"<>Completed"),Reorders!AC$13:AC$62,0))),"") | D25: =IFERROR(IF(16<=COUNTIFS('New Tooling Jobs'!A$13:A$62,"<>",'New Tooling Jobs'!E$13:E$62,"<>Completed"),INDEX('New Tooling Jobs'!E$13:E$62,MATCH(16,'New Tooling Jobs'!AG$13:AG$62,0)),INDEX(Reorders!E$13:E$62,MATCH(16-COUNTIFS('New Tooling Jobs'!A$13:A$62,"<>",'New Tooling Jobs'!E$13:E$62,"<>Completed"),Reorders!AC$13:AC$62,0))),"") | E25: =IFERROR(IF(16<=COUNTIFS('New Tooling Jobs'!A$13:A$62,"<>",'New Tooling Jobs'!E$13:E$62,"<>Completed"),INDEX('New Tooling Jobs'!G$13:G$62,MATCH(16,'New Tooling Jobs'!AG$13:AG$62,0)),INDEX(Reorders!G$13:G$62,MATCH(16-COUNTIFS('New Tooling Jobs'!A$13:A$62,"<>",'New Tooling Jobs'!E$13:E$62,"<>Completed"),Reorders!AC$13:AC$62,0))),"") | F25: =IFERROR(IF(16<=COUNTIFS('New Tooling Jobs'!A$13:A$62,"<>",'New Tooling Jobs'!E$13:E$62,"<>Completed"),INDEX('New Tooling Jobs'!H$13:H$62,MATCH(16,'New Tooling Jobs'!AG$13:AG$62,0)),INDEX(Reorders!H$13:H$62,MATCH(16-COUNTIFS('New Tooling Jobs'!A$13:A$62,"<>",'New Tooling Jobs'!E$13:E$62,"<>Completed"),Reorders!AC$13:AC$62,0))),"") | G25: =IFERROR(IF(16<=COUNTIFS('New Tooling Jobs'!A$13:A$62,"<>",'New Tooling Jobs'!E$13:E$62,"<>Completed"),INDEX('New Tooling Jobs'!I$13:I$62,MATCH(16,'New Tooling Jobs'!AG$13:AG$62,0)),INDEX(Reorders!I$13:I$62,MATCH(16-COUNTIFS('New Tooling Jobs'!A$13:A$62,"<>",'New Tooling Jobs'!E$13:E$62,"<>Completed"),Reorders!AC$13:AC$62,0))),"")
A26: =IFERROR(IF(17<=COUNTIFS('New Tooling Jobs'!A$13:A$62,"<>",'New Tooling Jobs'!E$13:E$62,"<>Completed"),INDEX('New Tooling Jobs'!A$13:A$62,MATCH(17,'New Tooling Jobs'!AG$13:AG$62,0)),INDEX(Reorders!A$13:A$62,MATCH(17-COUNTIFS('New Tooling Jobs'!A$13:A$62,"<>",'New Tooling Jobs'!E$13:E$62,"<>Completed"),Reorders!AC$13:AC$62,0))),"") | B26: =IFERROR(IF(17<=COUNTIFS('New Tooling Jobs'!A$13:A$62,"<>",'New Tooling Jobs'!E$13:E$62,"<>Completed"),IF(INDEX('New Tooling Jobs'!A$13:A$62,MATCH(17,'New Tooling Jobs'!AG$13:AG$62,0))<>"","New Tooling",""),IF(INDEX(Reorders!A$13:A$62,MATCH(17-COUNTIFS('New Tooling Jobs'!A$13:A$62,"<>",'New Tooling Jobs'!E$13:E$62,"<>Completed"),Reorders!AC$13:AC$62,0))<>"","Reorder","")),"") | C26: =IFERROR(IF(17<=COUNTIFS('New Tooling Jobs'!A$13:A$62,"<>",'New Tooling Jobs'!E$13:E$62,"<>Completed"),INDEX('New Tooling Jobs'!B$13:B$62,MATCH(17,'New Tooling Jobs'!AG$13:AG$62,0)),INDEX(Reorders!B$13:B$62,MATCH(17-COUNTIFS('New Tooling Jobs'!A$13:A$62,"<>",'New Tooling Jobs'!E$13:E$62,"<>Completed"),Reorders!AC$13:AC$62,0))),"") | D26: =IFERROR(IF(17<=COUNTIFS('New Tooling Jobs'!A$13:A$62,"<>",'New Tooling Jobs'!E$13:E$62,"<>Completed"),INDEX('New Tooling Jobs'!E$13:E$62,MATCH(17,'New Tooling Jobs'!AG$13:AG$62,0)),INDEX(Reorders!E$13:E$62,MATCH(17-COUNTIFS('New Tooling Jobs'!A$13:A$62,"<>",'New Tooling Jobs'!E$13:E$62,"<>Completed"),Reorders!AC$13:AC$62,0))),"") | E26: =IFERROR(IF(17<=COUNTIFS('New Tooling Jobs'!A$13:A$62,"<>",'New Tooling Jobs'!E$13:E$62,"<>Completed"),INDEX('New Tooling Jobs'!G$13:G$62,MATCH(17,'New Tooling Jobs'!AG$13:AG$62,0)),INDEX(Reorders!G$13:G$62,MATCH(17-COUNTIFS('New Tooling Jobs'!A$13:A$62,"<>",'New Tooling Jobs'!E$13:E$62,"<>Completed"),Reorders!AC$13:AC$62,0))),"") | F26: =IFERROR(IF(17<=COUNTIFS('New Tooling Jobs'!A$13:A$62,"<>",'New Tooling Jobs'!E$13:E$62,"<>Completed"),INDEX('New Tooling Jobs'!H$13:H$62,MATCH(17,'New Tooling Jobs'!AG$13:AG$62,0)),INDEX(Reorders!H$13:H$62,MATCH(17-COUNTIFS('New Tooling Jobs'!A$13:A$62,"<>",'New Tooling Jobs'!E$13:E$62,"<>Completed"),Reorders!AC$13:AC$62,0))),"") | G26: =IFERROR(IF(17<=COUNTIFS('New Tooling Jobs'!A$13:A$62,"<>",'New Tooling Jobs'!E$13:E$62,"<>Completed"),INDEX('New Tooling Jobs'!I$13:I$62,MATCH(17,'New Tooling Jobs'!AG$13:AG$62,0)),INDEX(Reorders!I$13:I$62,MATCH(17-COUNTIFS('New Tooling Jobs'!A$13:A$62,"<>",'New Tooling Jobs'!E$13:E$62,"<>Completed"),Reorders!AC$13:AC$62,0))),"")
A27: =IFERROR(IF(18<=COUNTIFS('New Tooling Jobs'!A$13:A$62,"<>",'New Tooling Jobs'!E$13:E$62,"<>Completed"),INDEX('New Tooling Jobs'!A$13:A$62,MATCH(18,'New Tooling Jobs'!AG$13:AG$62,0)),INDEX(Reorders!A$13:A$62,MATCH(18-COUNTIFS('New Tooling Jobs'!A$13:A$62,"<>",'New Tooling Jobs'!E$13:E$62,"<>Completed"),Reorders!AC$13:AC$62,0))),"") | B27: =IFERROR(IF(18<=COUNTIFS('New Tooling Jobs'!A$13:A$62,"<>",'New Tooling Jobs'!E$13:E$62,"<>Completed"),IF(INDEX('New Tooling Jobs'!A$13:A$62,MATCH(18,'New Tooling Jobs'!AG$13:AG$62,0))<>"","New Tooling",""),IF(INDEX(Reorders!A$13:A$62,MATCH(18-COUNTIFS('New Tooling Jobs'!A$13:A$62,"<>",'New Tooling Jobs'!E$13:E$62,"<>Completed"),Reorders!AC$13:AC$62,0))<>"","Reorder","")),"") | C27: =IFERROR(IF(18<=COUNTIFS('New Tooling Jobs'!A$13:A$62,"<>",'New Tooling Jobs'!E$13:E$62,"<>Completed"),INDEX('New Tooling Jobs'!B$13:B$62,MATCH(18,'New Tooling Jobs'!AG$13:AG$62,0)),INDEX(Reorders!B$13:B$62,MATCH(18-COUNTIFS('New Tooling Jobs'!A$13:A$62,"<>",'New Tooling Jobs'!E$13:E$62,"<>Completed"),Reorders!AC$13:AC$62,0))),"") | D27: =IFERROR(IF(18<=COUNTIFS('New Tooling Jobs'!A$13:A$62,"<>",'New Tooling Jobs'!E$13:E$62,"<>Completed"),INDEX('New Tooling Jobs'!E$13:E$62,MATCH(18,'New Tooling Jobs'!AG$13:AG$62,0)),INDEX(Reorders!E$13:E$62,MATCH(18-COUNTIFS('New Tooling Jobs'!A$13:A$62,"<>",'New Tooling Jobs'!E$13:E$62,"<>Completed"),Reorders!AC$13:AC$62,0))),"") | E27: =IFERROR(IF(18<=COUNTIFS('New Tooling Jobs'!A$13:A$62,"<>",'New Tooling Jobs'!E$13:E$62,"<>Completed"),INDEX('New Tooling Jobs'!G$13:G$62,MATCH(18,'New Tooling Jobs'!AG$13:AG$62,0)),INDEX(Reorders!G$13:G$62,MATCH(18-COUNTIFS('New Tooling Jobs'!A$13:A$62,"<>",'New Tooling Jobs'!E$13:E$62,"<>Completed"),Reorders!AC$13:AC$62,0))),"") | F27: =IFERROR(IF(18<=COUNTIFS('New Tooling Jobs'!A$13:A$62,"<>",'New Tooling Jobs'!E$13:E$62,"<>Completed"),INDEX('New Tooling Jobs'!H$13:H$62,MATCH(18,'New Tooling Jobs'!AG$13:AG$62,0)),INDEX(Reorders!H$13:H$62,MATCH(18-COUNTIFS('New Tooling Jobs'!A$13:A$62,"<>",'New Tooling Jobs'!E$13:E$62,"<>Completed"),Reorders!AC$13:AC$62,0))),"") | G27: =IFERROR(IF(18<=COUNTIFS('New Tooling Jobs'!A$13:A$62,"<>",'New Tooling Jobs'!E$13:E$62,"<>Completed"),INDEX('New Tooling Jobs'!I$13:I$62,MATCH(18,'New Tooling Jobs'!AG$13:AG$62,0)),INDEX(Reorders!I$13:I$62,MATCH(18-COUNTIFS('New Tooling Jobs'!A$13:A$62,"<>",'New Tooling Jobs'!E$13:E$62,"<>Completed"),Reorders!AC$13:AC$62,0))),"")
A28: =IFERROR(IF(19<=COUNTIFS('New Tooling Jobs'!A$13:A$62,"<>",'New Tooling Jobs'!E$13:E$62,"<>Completed"),INDEX('New Tooling Jobs'!A$13:A$62,MATCH(19,'New Tooling Jobs'!AG$13:AG$62,0)),INDEX(Reorders!A$13:A$62,MATCH(19-COUNTIFS('New Tooling Jobs'!A$13:A$62,"<>",'New Tooling Jobs'!E$13:E$62,"<>Completed"),Reorders!AC$13:AC$62,0))),"") | B28: =IFERROR(IF(19<=COUNTIFS('New Tooling Jobs'!A$13:A$62,"<>",'New Tooling Jobs'!E$13:E$62,"<>Completed"),IF(INDEX('New Tooling Jobs'!A$13:A$62,MATCH(19,'New Tooling Jobs'!AG$13:AG$62,0))<>"","New Tooling",""),IF(INDEX(Reorders!A$13:A$62,MATCH(19-COUNTIFS('New Tooling Jobs'!A$13:A$62,"<>",'New Tooling Jobs'!E$13:E$62,"<>Completed"),Reorders!AC$13:AC$62,0))<>"","Reorder","")),"") | C28: =IFERROR(IF(19<=COUNTIFS('New Tooling Jobs'!A$13:A$62,"<>",'New Tooling Jobs'!E$13:E$62,"<>Completed"),INDEX('New Tooling Jobs'!B$13:B$62,MATCH(19,'New Tooling Jobs'!AG$13:AG$62,0)),INDEX(Reorders!B$13:B$62,MATCH(19-COUNTIFS('New Tooling Jobs'!A$13:A$62,"<>",'New Tooling Jobs'!E$13:E$62,"<>Completed"),Reorders!AC$13:AC$62,0))),"") | D28: =IFERROR(IF(19<=COUNTIFS('New Tooling Jobs'!A$13:A$62,"<>",'New Tooling Jobs'!E$13:E$62,"<>Completed"),INDEX('New Tooling Jobs'!E$13:E$62,MATCH(19,'New Tooling Jobs'!AG$13:AG$62,0)),INDEX(Reorders!E$13:E$62,MATCH(19-COUNTIFS('New Tooling Jobs'!A$13:A$62,"<>",'New Tooling Jobs'!E$13:E$62,"<>Completed"),Reorders!AC$13:AC$62,0))),"") | E28: =IFERROR(IF(19<=COUNTIFS('New Tooling Jobs'!A$13:A$62,"<>",'New Tooling Jobs'!E$13:E$62,"<>Completed"),INDEX('New Tooling Jobs'!G$13:G$62,MATCH(19,'New Tooling Jobs'!AG$13:AG$62,0)),INDEX(Reorders!G$13:G$62,MATCH(19-COUNTIFS('New Tooling Jobs'!A$13:A$62,"<>",'New Tooling Jobs'!E$13:E$62,"<>Completed"),Reorders!AC$13:AC$62,0))),"") | F28: =IFERROR(IF(19<=COUNTIFS('New Tooling Jobs'!A$13:A$62,"<>",'New Tooling Jobs'!E$13:E$62,"<>Completed"),INDEX('New Tooling Jobs'!H$13:H$62,MATCH(19,'New Tooling Jobs'!AG$13:AG$62,0)),INDEX(Reorders!H$13:H$62,MATCH(19-COUNTIFS('New Tooling Jobs'!A$13:A$62,"<>",'New Tooling Jobs'!E$13:E$62,"<>Completed"),Reorders!AC$13:AC$62,0))),"") | G28: =IFERROR(IF(19<=COUNTIFS('New Tooling Jobs'!A$13:A$62,"<>",'New Tooling Jobs'!E$13:E$62,"<>Completed"),INDEX('New Tooling Jobs'!I$13:I$62,MATCH(19,'New Tooling Jobs'!AG$13:AG$62,0)),INDEX(Reorders!I$13:I$62,MATCH(19-COUNTIFS('New Tooling Jobs'!A$13:A$62,"<>",'New Tooling Jobs'!E$13:E$62,"<>Completed"),Reorders!AC$13:AC$62,0))),"")
A29: =IFERROR(IF(20<=COUNTIFS('New Tooling Jobs'!A$13:A$62,"<>",'New Tooling Jobs'!E$13:E$62,"<>Completed"),INDEX('New Tooling Jobs'!A$13:A$62,MATCH(20,'New Tooling Jobs'!AG$13:AG$62,0)),INDEX(Reorders!A$13:A$62,MATCH(20-COUNTIFS('New Tooling Jobs'!A$13:A$62,"<>",'New Tooling Jobs'!E$13:E$62,"<>Completed"),Reorders!AC$13:AC$62,0))),"") | B29: =IFERROR(IF(20<=COUNTIFS('New Tooling Jobs'!A$13:A$62,"<>",'New Tooling Jobs'!E$13:E$62,"<>Completed"),IF(INDEX('New Tooling Jobs'!A$13:A$62,MATCH(20,'New Tooling Jobs'!AG$13:AG$62,0))<>"","New Tooling",""),IF(INDEX(Reorders!A$13:A$62,MATCH(20-COUNTIFS('New Tooling Jobs'!A$13:A$62,"<>",'New Tooling Jobs'!E$13:E$62,"<>Completed"),Reorders!AC$13:AC$62,0))<>"","Reorder","")),"") | C29: =IFERROR(IF(20<=COUNTIFS('New Tooling Jobs'!A$13:A$62,"<>",'New Tooling Jobs'!E$13:E$62,"<>Completed"),INDEX('New Tooling Jobs'!B$13:B$62,MATCH(20,'New Tooling Jobs'!AG$13:AG$62,0)),INDEX(Reorders!B$13:B$62,MATCH(20-COUNTIFS('New Tooling Jobs'!A$13:A$62,"<>",'New Tooling Jobs'!E$13:E$62,"<>Completed"),Reorders!AC$13:AC$62,0))),"") | D29: =IFERROR(IF(20<=COUNTIFS('New Tooling Jobs'!A$13:A$62,"<>",'New Tooling Jobs'!E$13:E$62,"<>Completed"),INDEX('New Tooling Jobs'!E$13:E$62,MATCH(20,'New Tooling Jobs'!AG$13:AG$62,0)),INDEX(Reorders!E$13:E$62,MATCH(20-COUNTIFS('New Tooling Jobs'!A$13:A$62,"<>",'New Tooling Jobs'!E$13:E$62,"<>Completed"),Reorders!AC$13:AC$62,0))),"") | E29: =IFERROR(IF(20<=COUNTIFS('New Tooling Jobs'!A$13:A$62,"<>",'New Tooling Jobs'!E$13:E$62,"<>Completed"),INDEX('New Tooling Jobs'!G$13:G$62,MATCH(20,'New Tooling Jobs'!AG$13:AG$62,0)),INDEX(Reorders!G$13:G$62,MATCH(20-COUNTIFS('New Tooling Jobs'!A$13:A$62,"<>",'New Tooling Jobs'!E$13:E$62,"<>Completed"),Reorders!AC$13:AC$62,0))),"") | F29: =IFERROR(IF(20<=COUNTIFS('New Tooling Jobs'!A$13:A$62,"<>",'New Tooling Jobs'!E$13:E$62,"<>Completed"),INDEX('New Tooling Jobs'!H$13:H$62,MATCH(20,'New Tooling Jobs'!AG$13:AG$62,0)),INDEX(Reorders!H$13:H$62,MATCH(20-COUNTIFS('New Tooling Jobs'!A$13:A$62,"<>",'New Tooling Jobs'!E$13:E$62,"<>Completed"),Reorders!AC$13:AC$62,0))),"") | G29: =IFERROR(IF(20<=COUNTIFS('New Tooling Jobs'!A$13:A$62,"<>",'New Tooling Jobs'!E$13:E$62,"<>Completed"),INDEX('New Tooling Jobs'!I$13:I$62,MATCH(20,'New Tooling Jobs'!AG$13:AG$62,0)),INDEX(Reorders!I$13:I$62,MATCH(20-COUNTIFS('New Tooling Jobs'!A$13:A$62,"<>",'New Tooling Jobs'!E$13:E$62,"<>Completed"),Reorders!AC$13:AC$62,0))),"")
A30: =IFERROR(IF(21<=COUNTIFS('New Tooling Jobs'!A$13:A$62,"<>",'New Tooling Jobs'!E$13:E$62,"<>Completed"),INDEX('New Tooling Jobs'!A$13:A$62,MATCH(21,'New Tooling Jobs'!AG$13:AG$62,0)),INDEX(Reorders!A$13:A$62,MATCH(21-COUNTIFS('New Tooling Jobs'!A$13:A$62,"<>",'New Tooling Jobs'!E$13:E$62,"<>Completed"),Reorders!AC$13:AC$62,0))),"") | B30: =IFERROR(IF(21<=COUNTIFS('New Tooling Jobs'!A$13:A$62,"<>",'New Tooling Jobs'!E$13:E$62,"<>Completed"),IF(INDEX('New Tooling Jobs'!A$13:A$62,MATCH(21,'New Tooling Jobs'!AG$13:AG$62,0))<>"","New Tooling",""),IF(INDEX(Reorders!A$13:A$62,MATCH(21-COUNTIFS('New Tooling Jobs'!A$13:A$62,"<>",'New Tooling Jobs'!E$13:E$62,"<>Completed"),Reorders!AC$13:AC$62,0))<>"","Reorder","")),"") | C30: =IFERROR(IF(21<=COUNTIFS('New Tooling Jobs'!A$13:A$62,"<>",'New Tooling Jobs'!E$13:E$62,"<>Completed"),INDEX('New Tooling Jobs'!B$13:B$62,MATCH(21,'New Tooling Jobs'!AG$13:AG$62,0)),INDEX(Reorders!B$13:B$62,MATCH(21-COUNTIFS('New Tooling Jobs'!A$13:A$62,"<>",'New Tooling Jobs'!E$13:E$62,"<>Completed"),Reorders!AC$13:AC$62,0))),"") | D30: =IFERROR(IF(21<=COUNTIFS('New Tooling Jobs'!A$13:A$62,"<>",'New Tooling Jobs'!E$13:E$62,"<>Completed"),INDEX('New Tooling Jobs'!E$13:E$62,MATCH(21,'New Tooling Jobs'!AG$13:AG$62,0)),INDEX(Reorders!E$13:E$62,MATCH(21-COUNTIFS('New Tooling Jobs'!A$13:A$62,"<>",'New Tooling Jobs'!E$13:E$62,"<>Completed"),Reorders!AC$13:AC$62,0))),"") | E30: =IFERROR(IF(21<=COUNTIFS('New Tooling Jobs'!A$13:A$62,"<>",'New Tooling Jobs'!E$13:E$62,"<>Completed"),INDEX('New Tooling Jobs'!G$13:G$62,MATCH(21,'New Tooling Jobs'!AG$13:AG$62,0)),INDEX(Reorders!G$13:G$62,MATCH(21-COUNTIFS('New Tooling Jobs'!A$13:A$62,"<>",'New Tooling Jobs'!E$13:E$62,"<>Completed"),Reorders!AC$13:AC$62,0))),"") | F30: =IFERROR(IF(21<=COUNTIFS('New Tooling Jobs'!A$13:A$62,"<>",'New Tooling Jobs'!E$13:E$62,"<>Completed"),INDEX('New Tooling Jobs'!H$13:H$62,MATCH(21,'New Tooling Jobs'!AG$13:AG$62,0)),INDEX(Reorders!H$13:H$62,MATCH(21-COUNTIFS('New Tooling Jobs'!A$13:A$62,"<>",'New Tooling Jobs'!E$13:E$62,"<>Completed"),Reorders!AC$13:AC$62,0))),"") | G30: =IFERROR(IF(21<=COUNTIFS('New Tooling Jobs'!A$13:A$62,"<>",'New Tooling Jobs'!E$13:E$62,"<>Completed"),INDEX('New Tooling Jobs'!I$13:I$62,MATCH(21,'New Tooling Jobs'!AG$13:AG$62,0)),INDEX(Reorders!I$13:I$62,MATCH(21-COUNTIFS('New Tooling Jobs'!A$13:A$62,"<>",'New Tooling Jobs'!E$13:E$62,"<>Completed"),Reorders!AC$13:AC$62,0))),"")
A31: =IFERROR(IF(22<=COUNTIFS('New Tooling Jobs'!A$13:A$62,"<>",'New Tooling Jobs'!E$13:E$62,"<>Completed"),INDEX('New Tooling Jobs'!A$13:A$62,MATCH(22,'New Tooling Jobs'!AG$13:AG$62,0)),INDEX(Reorders!A$13:A$62,MATCH(22-COUNTIFS('New Tooling Jobs'!A$13:A$62,"<>",'New Tooling Jobs'!E$13:E$62,"<>Completed"),Reorders!AC$13:AC$62,0))),"") | B31: =IFERROR(IF(22<=COUNTIFS('New Tooling Jobs'!A$13:A$62,"<>",'New Tooling Jobs'!E$13:E$62,"<>Completed"),IF(INDEX('New Tooling Jobs'!A$13:A$62,MATCH(22,'New Tooling Jobs'!AG$13:AG$62,0))<>"","New Tooling",""),IF(INDEX(Reorders!A$13:A$62,MATCH(22-COUNTIFS('New Tooling Jobs'!A$13:A$62,"<>",'New Tooling Jobs'!E$13:E$62,"<>Completed"),Reorders!AC$13:AC$62,0))<>"","Reorder","")),"") | C31: =IFERROR(IF(22<=COUNTIFS('New Tooling Jobs'!A$13:A$62,"<>",'New Tooling Jobs'!E$13:E$62,"<>Completed"),INDEX('New Tooling Jobs'!B$13:B$62,MATCH(22,'New Tooling Jobs'!AG$13:AG$62,0)),INDEX(Reorders!B$13:B$62,MATCH(22-COUNTIFS('New Tooling Jobs'!A$13:A$62,"<>",'New Tooling Jobs'!E$13:E$62,"<>Completed"),Reorders!AC$13:AC$62,0))),"") | D31: =IFERROR(IF(22<=COUNTIFS('New Tooling Jobs'!A$13:A$62,"<>",'New Tooling Jobs'!E$13:E$62,"<>Completed"),INDEX('New Tooling Jobs'!E$13:E$62,MATCH(22,'New Tooling Jobs'!AG$13:AG$62,0)),INDEX(Reorders!E$13:E$62,MATCH(22-COUNTIFS('New Tooling Jobs'!A$13:A$62,"<>",'New Tooling Jobs'!E$13:E$62,"<>Completed"),Reorders!AC$13:AC$62,0))),"") | E31: =IFERROR(IF(22<=COUNTIFS('New Tooling Jobs'!A$13:A$62,"<>",'New Tooling Jobs'!E$13:E$62,"<>Completed"),INDEX('New Tooling Jobs'!G$13:G$62,MATCH(22,'New Tooling Jobs'!AG$13:AG$62,0)),INDEX(Reorders!G$13:G$62,MATCH(22-COUNTIFS('New Tooling Jobs'!A$13:A$62,"<>",'New Tooling Jobs'!E$13:E$62,"<>Completed"),Reorders!AC$13:AC$62,0))),"") | F31: =IFERROR(IF(22<=COUNTIFS('New Tooling Jobs'!A$13:A$62,"<>",'New Tooling Jobs'!E$13:E$62,"<>Completed"),INDEX('New Tooling Jobs'!H$13:H$62,MATCH(22,'New Tooling Jobs'!AG$13:AG$62,0)),INDEX(Reorders!H$13:H$62,MATCH(22-COUNTIFS('New Tooling Jobs'!A$13:A$62,"<>",'New Tooling Jobs'!E$13:E$62,"<>Completed"),Reorders!AC$13:AC$62,0))),"") | G31: =IFERROR(IF(22<=COUNTIFS('New Tooling Jobs'!A$13:A$62,"<>",'New Tooling Jobs'!E$13:E$62,"<>Completed"),INDEX('New Tooling Jobs'!I$13:I$62,MATCH(22,'New Tooling Jobs'!AG$13:AG$62,0)),INDEX(Reorders!I$13:I$62,MATCH(22-COUNTIFS('New Tooling Jobs'!A$13:A$62,"<>",'New Tooling Jobs'!E$13:E$62,"<>Completed"),Reorders!AC$13:AC$62,0))),"")
A32: =IFERROR(IF(23<=COUNTIFS('New Tooling Jobs'!A$13:A$62,"<>",'New Tooling Jobs'!E$13:E$62,"<>Completed"),INDEX('New Tooling Jobs'!A$13:A$62,MATCH(23,'New Tooling Jobs'!AG$13:AG$62,0)),INDEX(Reorders!A$13:A$62,MATCH(23-COUNTIFS('New Tooling Jobs'!A$13:A$62,"<>",'New Tooling Jobs'!E$13:E$62,"<>Completed"),Reorders!AC$13:AC$62,0))),"") | B32: =IFERROR(IF(23<=COUNTIFS('New Tooling Jobs'!A$13:A$62,"<>",'New Tooling Jobs'!E$13:E$62,"<>Completed"),IF(INDEX('New Tooling Jobs'!A$13:A$62,MATCH(23,'New Tooling Jobs'!AG$13:AG$62,0))<>"","New Tooling",""),IF(INDEX(Reorders!A$13:A$62,MATCH(23-COUNTIFS('New Tooling Jobs'!A$13:A$62,"<>",'New Tooling Jobs'!E$13:E$62,"<>Completed"),Reorders!AC$13:AC$62,0))<>"","Reorder","")),"") | C32: =IFERROR(IF(23<=COUNTIFS('New Tooling Jobs'!A$13:A$62,"<>",'New Tooling Jobs'!E$13:E$62,"<>Completed"),INDEX('New Tooling Jobs'!B$13:B$62,MATCH(23,'New Tooling Jobs'!AG$13:AG$62,0)),INDEX(Reorders!B$13:B$62,MATCH(23-COUNTIFS('New Tooling Jobs'!A$13:A$62,"<>",'New Tooling Jobs'!E$13:E$62,"<>Completed"),Reorders!AC$13:AC$62,0))),"") | D32: =IFERROR(IF(23<=COUNTIFS('New Tooling Jobs'!A$13:A$62,"<>",'New Tooling Jobs'!E$13:E$62,"<>Completed"),INDEX('New Tooling Jobs'!E$13:E$62,MATCH(23,'New Tooling Jobs'!AG$13:AG$62,0)),INDEX(Reorders!E$13:E$62,MATCH(23-COUNTIFS('New Tooling Jobs'!A$13:A$62,"<>",'New Tooling Jobs'!E$13:E$62,"<>Completed"),Reorders!AC$13:AC$62,0))),"") | E32: =IFERROR(IF(23<=COUNTIFS('New Tooling Jobs'!A$13:A$62,"<>",'New Tooling Jobs'!E$13:E$62,"<>Completed"),INDEX('New Tooling Jobs'!G$13:G$62,MATCH(23,'New Tooling Jobs'!AG$13:AG$62,0)),INDEX(Reorders!G$13:G$62,MATCH(23-COUNTIFS('New Tooling Jobs'!A$13:A$62,"<>",'New Tooling Jobs'!E$13:E$62,"<>Completed"),Reorders!AC$13:AC$62,0))),"") | F32: =IFERROR(IF(23<=COUNTIFS('New Tooling Jobs'!A$13:A$62,"<>",'New Tooling Jobs'!E$13:E$62,"<>Completed"),INDEX('New Tooling Jobs'!H$13:H$62,MATCH(23,'New Tooling Jobs'!AG$13:AG$62,0)),INDEX(Reorders!H$13:H$62,MATCH(23-COUNTIFS('New Tooling Jobs'!A$13:A$62,"<>",'New Tooling Jobs'!E$13:E$62,"<>Completed"),Reorders!AC$13:AC$62,0))),"") | G32: =IFERROR(IF(23<=COUNTIFS('New Tooling Jobs'!A$13:A$62,"<>",'New Tooling Jobs'!E$13:E$62,"<>Completed"),INDEX('New Tooling Jobs'!I$13:I$62,MATCH(23,'New Tooling Jobs'!AG$13:AG$62,0)),INDEX(Reorders!I$13:I$62,MATCH(23-COUNTIFS('New Tooling Jobs'!A$13:A$62,"<>",'New Tooling Jobs'!E$13:E$62,"<>Completed"),Reorders!AC$13:AC$62,0))),"")
A33: =IFERROR(IF(24<=COUNTIFS('New Tooling Jobs'!A$13:A$62,"<>",'New Tooling Jobs'!E$13:E$62,"<>Completed"),INDEX('New Tooling Jobs'!A$13:A$62,MATCH(24,'New Tooling Jobs'!AG$13:AG$62,0)),INDEX(Reorders!A$13:A$62,MATCH(24-COUNTIFS('New Tooling Jobs'!A$13:A$62,"<>",'New Tooling Jobs'!E$13:E$62,"<>Completed"),Reorders!AC$13:AC$62,0))),"") | B33: =IFERROR(IF(24<=COUNTIFS('New Tooling Jobs'!A$13:A$62,"<>",'New Tooling Jobs'!E$13:E$62,"<>Completed"),IF(INDEX('New Tooling Jobs'!A$13:A$62,MATCH(24,'New Tooling Jobs'!AG$13:AG$62,0))<>"","New Tooling",""),IF(INDEX(Reorders!A$13:A$62,MATCH(24-COUNTIFS('New Tooling Jobs'!A$13:A$62,"<>",'New Tooling Jobs'!E$13:E$62,"<>Completed"),Reorders!AC$13:AC$62,0))<>"","Reorder","")),"") | C33: =IFERROR(IF(24<=COUNTIFS('New Tooling Jobs'!A$13:A$62,"<>",'New Tooling Jobs'!E$13:E$62,"<>Completed"),INDEX('New Tooling Jobs'!B$13:B$62,MATCH(24,'New Tooling Jobs'!AG$13:AG$62,0)),INDEX(Reorders!B$13:B$62,MATCH(24-COUNTIFS('New Tooling Jobs'!A$13:A$62,"<>",'New Tooling Jobs'!E$13:E$62,"<>Completed"),Reorders!AC$13:AC$62,0))),"") | D33: =IFERROR(IF(24<=COUNTIFS('New Tooling Jobs'!A$13:A$62,"<>",'New Tooling Jobs'!E$13:E$62,"<>Completed"),INDEX('New Tooling Jobs'!E$13:E$62,MATCH(24,'New Tooling Jobs'!AG$13:AG$62,0)),INDEX(Reorders!E$13:E$62,MATCH(24-COUNTIFS('New Tooling Jobs'!A$13:A$62,"<>",'New Tooling Jobs'!E$13:E$62,"<>Completed"),Reorders!AC$13:AC$62,0))),"") | E33: =IFERROR(IF(24<=COUNTIFS('New Tooling Jobs'!A$13:A$62,"<>",'New Tooling Jobs'!E$13:E$62,"<>Completed"),INDEX('New Tooling Jobs'!G$13:G$62,MATCH(24,'New Tooling Jobs'!AG$13:AG$62,0)),INDEX(Reorders!G$13:G$62,MATCH(24-COUNTIFS('New Tooling Jobs'!A$13:A$62,"<>",'New Tooling Jobs'!E$13:E$62,"<>Completed"),Reorders!AC$13:AC$62,0))),"") | F33: =IFERROR(IF(24<=COUNTIFS('New Tooling Jobs'!A$13:A$62,"<>",'New Tooling Jobs'!E$13:E$62,"<>Completed"),INDEX('New Tooling Jobs'!H$13:H$62,MATCH(24,'New Tooling Jobs'!AG$13:AG$62,0)),INDEX(Reorders!H$13:H$62,MATCH(24-COUNTIFS('New Tooling Jobs'!A$13:A$62,"<>",'New Tooling Jobs'!E$13:E$62,"<>Completed"),Reorders!AC$13:AC$62,0))),"") | G33: =IFERROR(IF(24<=COUNTIFS('New Tooling Jobs'!A$13:A$62,"<>",'New Tooling Jobs'!E$13:E$62,"<>Completed"),INDEX('New Tooling Jobs'!I$13:I$62,MATCH(24,'New Tooling Jobs'!AG$13:AG$62,0)),INDEX(Reorders!I$13:I$62,MATCH(24-COUNTIFS('New Tooling Jobs'!A$13:A$62,"<>",'New Tooling Jobs'!E$13:E$62,"<>Completed"),Reorders!AC$13:AC$62,0))),"")
